Workbook

Sheet Chart
B2: Since June 2020, the Nifty and its expected earnings have both grown about 2.3 times
B3: That is why the forward P/E is back near 17x, the level Bloomberg flagged as the cheapest since 2020. Top: price and expected earnings, indexed to 100 on 2 Jun 2020.
B4: Bottom: the 12-month forward P/E, which is price divided by expected earnings.
B6: ="Nifty 50 "&TEXT(Summary!C8,"#,##0")&" → "&TEXT(Summary!C9,"#,##0")&" ("&TEXT(Summary!F8,"0.0")&"x)" -> Nifty 50 9,979 → 22,780 (2.3x) | H6: ="Forward EPS ₹"&TEXT(Summary!E8,"#,##0")&" → ₹"&TEXT(Summary!E9,"#,##0")&" ("&TEXT(Summary!G8,"0.0")&"x)" -> Forward EPS ₹588 → ₹1,345 (2.3x) | N6: ="Forward P/E "&TEXT(Summary!D8,"0.0")&"x → "&TEXT(Summary!D9,"0.0")&"x" -> Forward P/E 17.0x → 16.9x
B41: Source: Bloomberg (Nifty 50 12-month forward P/E, digitised from Bloomberg's chart; accurate to about ±0.4x), NSE via Yahoo Finance (Nifty 50 closes). Forward EPS = Nifty close ÷ forward P/E, 21-day median. Data to 28 Sep 2026.
B42: Expected earnings are analyst forecasts for the next 12 months. FY27 consensus fell from ₹1,357 to ₹1,235 in the year to May 2026 (JM Financial, Bloomberg consensus). Actual reported Nifty EPS rose from ₹539 (FY21) to ₹1,065 (FY26), per Motilal Oswal.
B44: 1 Finance | SEBI Registered Investment Advisor. This content is for information and educational purposes only. Please consult a Qualified Financial Advisor before making investment decisions.

Sheet Data
A1: Date | B1: Nifty 50 close | C1: Forward P/E, digitised (band midpoint) | D1: Band: lowest possible P/E | E1: Band: highest possible P/E | F1: Implied forward EPS (raw) | G1: Forward EPS (21-day median) | H1: Forward P/E (rebuilt = close / forward EPS) | I1: Nifty 50 index (base = 100) | J1: Forward EPS index (base = 100) | K1: Latest P/E (reference line) | L1: Rebuilt P/E inside chart band?
A2: 43769 | B2: 11877.45 | C2: 18.7368 | D2: 18.723 | E2: 18.7506 | F2: =IF(C2="","",B2/C2) -> 633.91027 | G2: =MEDIAN(F2:F12) -> 643.28945 | H2: =B2/G2 -> 18.463617 | I2: =B2/Summary!$C$8*100 -> 119.02326 | J2: =G2/Summary!$E$8*100 -> 109.33079 | K2: =Summary!$D$9 -> 16.937449 | L2: =IF(OR(D2="",E2=""),"edge hidden",IF(AND(H2>=D2-0.02,H2<=E2+0.02),"yes","no")) -> no
A3: 43770 | B3: 11890.6 | C3: 18.6895 | D3: 18.6285 | E3: 18.7506 | F3: =IF(C3="","",B3/C3) -> 636.2182 | G3: =MEDIAN(F2:F13) -> 643.249 | H3: =B3/G3 -> 18.485221 | I3: =B3/Summary!$C$8*100 -> 119.15503 | J3: =G3/Summary!$E$8*100 -> 109.32391 | K3: =Summary!$D$9 -> 16.937449 | L3: =IF(OR(D3="",E3=""),"edge hidden",IF(AND(H3>=D3-0.02,H3<=E3+0.02),"yes","no")) -> no
A4: 43773 | B4: 11941.3 | C4: 18.6541 | D4: 18.5734 | E4: 18.7348 | F4: =IF(C4="","",B4/C4) -> 640.14345 | G4: =MEDIAN(F2:F14) -> 643.28945 | H4: =B4/G4 -> 18.562872 | I4: =B4/Summary!$C$8*100 -> 119.6631 | J4: =G4/Summary!$E$8*100 -> 109.33079 | K4: =Summary!$D$9 -> 16.937449 | L4: =IF(OR(D4="",E4=""),"edge hidden",IF(AND(H4>=D4-0.02,H4<=E4+0.02),"yes","no")) -> yes
A5: 43774 | B5: 11917.2 | C5: 18.6147 | D5: 18.5104 | E5: 18.7191 | F5: =IF(C5="","",B5/C5) -> 640.20371 | G5: =MEDIAN(F2:F15) -> 643.3975 | H5: =B5/G5 -> 18.522298 | I5: =B5/Summary!$C$8*100 -> 119.42159 | J5: =G5/Summary!$E$8*100 -> 109.34915 | K5: =Summary!$D$9 -> 16.937449 | L5: =IF(OR(D5="",E5=""),"edge hidden",IF(AND(H5>=D5-0.02,H5<=E5+0.02),"yes","no")) -> yes
A6: 43775 | B6: 11966.05 | C6: 18.5951 | D6: 18.4868 | E6: 18.7033 | F6: =IF(C6="","",B6/C6) -> 643.50555 | G6: =MEDIAN(F2:F16) -> 643.50555 | H6: =B6/G6 -> 18.5951 | I6: =B6/Summary!$C$8*100 -> 119.91111 | J6: =G6/Summary!$E$8*100 -> 109.36752 | K6: =Summary!$D$9 -> 16.937449 | L6: =IF(OR(D6="",E6=""),"edge hidden",IF(AND(H6>=D6-0.02,H6<=E6+0.02),"yes","no")) -> yes
A7: 43776 | B7: 12012.05 | C7: 18.5872 | D7: 18.471 | E7: 18.7033 | F7: =IF(C7="","",B7/C7) -> 646.25387 | G7: =MEDIAN(F2:F17) -> 643.48012 | H7: =B7/G7 -> 18.667321 | I7: =B7/Summary!$C$8*100 -> 120.37208 | J7: =G7/Summary!$E$8*100 -> 109.36319 | K7: =Summary!$D$9 -> 16.937449 | L7: =IF(OR(D7="",E7=""),"edge hidden",IF(AND(H7>=D7-0.02,H7<=E7+0.02),"yes","no")) -> yes
A8: 43777 | B8: 11908.15 | C8: 18.5793 | D8: 18.4632 | E8: 18.6954 | F8: =IF(C8="","",B8/C8) -> 640.93642 | G8: =MEDIAN(F2:F18) -> 643.50555 | H8: =B8/G8 -> 18.505124 | I8: =B8/Summary!$C$8*100 -> 119.3309 | J8: =G8/Summary!$E$8*100 -> 109.36752 | K8: =Summary!$D$9 -> 16.937449 | L8: =IF(OR(D8="",E8=""),"edge hidden",IF(AND(H8>=D8-0.02,H8<=E8+0.02),"yes","no")) -> yes
A9: 43780 | B9: 11913.45 | C9: 18.4139 | D9: 18.3451 | E9: 18.4828 | F9: =IF(C9="","",B9/C9) -> 646.98136 | G9: =MEDIAN(F2:F19) -> 644.18895 | H9: =B9/G9 -> 18.49372 | I9: =B9/Summary!$C$8*100 -> 119.38401 | J9: =G9/Summary!$E$8*100 -> 109.48366 | K9: =Summary!$D$9 -> 16.937449 | L9: =IF(OR(D9="",E9=""),"edge hidden",IF(AND(H9>=D9-0.02,H9<=E9+0.02),"yes","no")) -> yes
A10: 43782 | B10: 11840.45 | C10: 18.4061 | D10: 18.3372 | E10: 18.475 | F10: =IF(C10="","",B10/C10) -> 643.28945 | G10: =MEDIAN(F2:F20) -> 644.87235 | H10: =B10/G10 -> 18.360921 | I10: =B10/Summary!$C$8*100 -> 118.65248 | J10: =G10/Summary!$E$8*100 -> 109.59981 | K10: =Summary!$D$9 -> 16.937449 | L10: =IF(OR(D10="",E10=""),"edge hidden",IF(AND(H10>=D10-0.02,H10<=E10+0.02),"yes","no")) -> yes
A11: 43783 | B11: 11872.1 | C11: 18.41 | D11: 18.3451 | E11: 18.475 | F11: =IF(C11="","",B11/C11) -> 644.87235 | G11: =MEDIAN(F2:F21) -> 645.29958 | H11: =B11/G11 -> 18.397812 | I11: =B11/Summary!$C$8*100 -> 118.96965 | J11: =G11/Summary!$E$8*100 -> 109.67242 | K11: =Summary!$D$9 -> 16.937449 | L11: =IF(OR(D11="",E11=""),"edge hidden",IF(AND(H11>=D11-0.02,H11<=E11+0.02),"yes","no")) -> yes
A12: 43784 | B12: 11895.45 | C12: 18.4218 | D12: 18.3608 | E12: 18.4828 | F12: =IF(C12="","",B12/C12) -> 645.7268 | G12: =MEDIAN(F2:F22) -> 645.7268 | H12: =B12/G12 -> 18.4218 | I12: =B12/Summary!$C$8*100 -> 119.20364 | J12: =G12/Summary!$E$8*100 -> 109.74503 | K12: =Summary!$D$9 -> 16.937449 | L12: =IF(OR(D12="",E12=""),"edge hidden",IF(AND(H12>=D12-0.02,H12<=E12+0.02),"yes","no")) -> yes
A13: 43787 | B13: 11884.5 | C13: 18.4769 | D13: 18.4002 | E13: 18.5537 | F13: =IF(C13="","",B13/C13) -> 643.20855 | G13: =MEDIAN(F3:F23) -> 645.94153 | H13: =B13/G13 -> 18.398724 | I13: =B13/Summary!$C$8*100 -> 119.09391 | J13: =G13/Summary!$E$8*100 -> 109.78152 | K13: =Summary!$D$9 -> 16.937449 | L13: =IF(OR(D13="",E13=""),"edge hidden",IF(AND(H13>=D13-0.02,H13<=E13+0.02),"yes","no")) -> yes
A14: 43788 | B14: 11940.1 | C14: 18.4848 | D14: 18.408 | E14: 18.5616 | F14: =IF(C14="","",B14/C14) -> 645.94153 | G14: =MEDIAN(F4:F24) -> 646.25387 | H14: =B14/G14 -> 18.475866 | I14: =B14/Summary!$C$8*100 -> 119.65107 | J14: =G14/Summary!$E$8*100 -> 109.83461 | K14: =Summary!$D$9 -> 16.937449 | L14: =IF(OR(D14="",E14=""),"edge hidden",IF(AND(H14>=D14-0.02,H14<=E14+0.02),"yes","no")) -> yes
A15: 43789 | B15: 11999.1 | C15: 18.4888 | D15: 18.408 | E15: 18.5695 | F15: =IF(C15="","",B15/C15) -> 648.9929 | G15: =MEDIAN(F5:F25) -> 646.50721 | H15: =B15/G15 -> 18.559886 | I15: =B15/Summary!$C$8*100 -> 120.24231 | J15: =G15/Summary!$E$8*100 -> 109.87766 | K15: =Summary!$D$9 -> 16.937449 | L15: =IF(OR(D15="",E15=""),"edge hidden",IF(AND(H15>=D15-0.02,H15<=E15+0.02),"yes","no")) -> yes
A16: 43790 | B16: 11968.4 | C16: 18.5124 | D16: 18.408 | E16: 18.6167 | F16: =IF(C16="","",B16/C16) -> 646.50721 | G16: =MEDIAN(F6:F26) -> 646.98136 | H16: =B16/G16 -> 18.498833 | I16: =B16/Summary!$C$8*100 -> 119.93466 | J16: =G16/Summary!$E$8*100 -> 109.95825 | K16: =Summary!$D$9 -> 16.937449 | L16: =IF(OR(D16="",E16=""),"edge hidden",IF(AND(H16>=D16-0.02,H16<=E16+0.02),"yes","no")) -> yes
A17: 43791 | B17: 11914.4 | C17: 18.5163 | D17: 18.408 | E17: 18.6246 | F17: =IF(C17="","",B17/C17) -> 643.45469 | G17: =MEDIAN(F7:F27) -> 648.9929 | H17: =B17/G17 -> 18.35829 | I17: =B17/Summary!$C$8*100 -> 119.39353 | J17: =G17/Summary!$E$8*100 -> 110.30012 | K17: =Summary!$D$9 -> 16.937449 | L17: =IF(OR(D17="",E17=""),"edge hidden",IF(AND(H17>=D17-0.02,H17<=E17+0.02),"yes","no")) -> no
A18: 43794 | B18: 12073.75 | C18: 18.536 | D18: 18.4159 | E18: 18.6561 | F18: =IF(C18="","",B18/C18) -> 651.36761 | G18: =MEDIAN(F8:F28) -> 649.00959 | H18: =B18/G18 -> 18.603346 | I18: =B18/Summary!$C$8*100 -> 120.99037 | J18: =G18/Summary!$E$8*100 -> 110.30296 | K18: =Summary!$D$9 -> 16.937449 | L18: =IF(OR(D18="",E18=""),"edge hidden",IF(AND(H18>=D18-0.02,H18<=E18+0.02),"yes","no")) -> yes
A19: 43795 | B19: 12037.7 | C19: 18.5478 | D19: 18.4317 | E19: 18.6639 | F19: =IF(C19="","",B19/C19) -> 649.00959 | G19: =MEDIAN(F9:F29) -> 650.54959 | H19: =B19/G19 -> 18.503893 | I19: =B19/Summary!$C$8*100 -> 120.62911 | J19: =G19/Summary!$E$8*100 -> 110.56469 | K19: =Summary!$D$9 -> 16.937449 | L19: =IF(OR(D19="",E19=""),"edge hidden",IF(AND(H19>=D19-0.02,H19<=E19+0.02),"yes","no")) -> yes
A20: 43796 | B20: 12100.7 | C20: 18.5557 | D20: 18.4474 | E20: 18.6639 | F20: =IF(C20="","",B20/C20) -> 652.12846 | G20: =MEDIAN(F10:F30) -> 651.36761 | H20: =B20/G20 -> 18.577374 | I20: =B20/Summary!$C$8*100 -> 121.26043 | J20: =G20/Summary!$E$8*100 -> 110.70372 | K20: =Summary!$D$9 -> 16.937449 | L20: =IF(OR(D20="",E20=""),"edge hidden",IF(AND(H20>=D20-0.02,H20<=E20+0.02),"yes","no")) -> yes
A21: 43797 | B21: 12151.15 | C21: 18.5439 | D21: 18.4317 | E21: 18.6561 | F21: =IF(C21="","",B21/C21) -> 655.264 | G21: =MEDIAN(F11:F31) -> 652.12846 | H21: =B21/G21 -> 18.633062 | I21: =B21/Summary!$C$8*100 -> 121.76599 | J21: =G21/Summary!$E$8*100 -> 110.83303 | K21: =Summary!$D$9 -> 16.937449 | L21: =IF(OR(D21="",E21=""),"edge hidden",IF(AND(H21>=D21-0.02,H21<=E21+0.02),"yes","no")) -> yes
A22: 43798 | B22: 12056.05 | C22: 18.5321 | D22: 18.4159 | E22: 18.6482 | F22: =IF(C22="","",B22/C22) -> 650.54959 | G22: =MEDIAN(F12:F32) -> 652.41171 | H22: =B22/G22 -> 18.479205 | I22: =B22/Summary!$C$8*100 -> 120.813 | J22: =G22/Summary!$E$8*100 -> 110.88117 | K22: =Summary!$D$9 -> 16.937449 | L22: =IF(OR(D22="",E22=""),"edge hidden",IF(AND(H22>=D22-0.02,H22<=E22+0.02),"yes","no")) -> yes
A23: 43801 | B23: 12048.2 | C23: 18.3706 | D23: 18.2427 | E23: 18.4986 | F23: =IF(C23="","",B23/C23) -> 655.8414 | G23: =MEDIAN(F13:F33) -> 653.0003 | H23: =B23/G23 -> 18.450527 | I23: =B23/Summary!$C$8*100 -> 120.73433 | J23: =G23/Summary!$E$8*100 -> 110.9812 | K23: =Summary!$D$9 -> 16.937449 | L23: =IF(OR(D23="",E23=""),"edge hidden",IF(AND(H23>=D23-0.02,H23<=E23+0.02),"yes","no")) -> yes
... A145: 43984 | B145: 9979.1 | C145: 16.8076 | D145: 16.3529 | E145: 17.2624 | F145: =IF(C145="","",B145/C145) -> 593.72546 | G145: =MEDIAN(F135:F155) -> 588.38819 | H145: =B145/G145 -> 16.960062 | I145: =B145/Summary!$C$8*100 -> 100 | J145: =G145/Summary!$E$8*100 -> 100 | K145: =Summary!$D$9 -> 16.937449 | L145: =IF(OR(D145="",E145=""),"edge hidden",IF(AND(H145>=D145-0.02,H145<=E145+0.02),"yes","no")) -> yes
A146: 43985 | B146: 10061.55 | E146: 17.286 | F146: =IF(C146="","",B146/C146) | G146: =MEDIAN(F136:F156) -> 589.35581 | H146: =B146/G146 -> 17.072115 | I146: =B146/Summary!$C$8*100 -> 100.82623 | J146: =G146/Summary!$E$8*100 -> 100.16445 | K146: =Summary!$D$9 -> 16.937449 | L146: =IF(OR(D146="",E146=""),"edge hidden",IF(AND(H146>=D146-0.02,H146<=E146+0.02),"yes","no")) -> edge hidden
A147: 43986 | B147: 10029.1 | D147: 16.975 | F147: =IF(C147="","",B147/C147) | G147: =MEDIAN(F137:F157) -> 589.35581 | H147: =B147/G147 -> 17.017054 | I147: =B147/Summary!$C$8*100 -> 100.50105 | J147: =G147/Summary!$E$8*100 -> 100.16445 | K147: =Summary!$D$9 -> 16.937449 | L147: =IF(OR(D147="",E147=""),"edge hidden",IF(AND(H147>=D147-0.02,H147<=E147+0.02),"yes","no")) -> edge hidden
A148: 43987 | B148: 10142.15 | D148: 17.0537 | F148: =IF(C148="","",B148/C148) | G148: =MEDIAN(F138:F158) -> 588.38689 | H148: =B148/G148 -> 17.237213 | I148: =B148/Summary!$C$8*100 -> 101.63391 | J148: =G148/Summary!$E$8*100 -> 99.999778 | K148: =Summary!$D$9 -> 16.937449 | L148: =IF(OR(D148="",E148=""),"edge hidden",IF(AND(H148>=D148-0.02,H148<=E148+0.02),"yes","no")) -> edge hidden
A149: 43990 | B149: 10167.45 | D149: 17.038 | F149: =IF(C149="","",B149/C149) | G149: =MEDIAN(F139:F159) -> 588.01942 | H149: =B149/G149 -> 17.291011 | I149: =B149/Summary!$C$8*100 -> 101.88744 | J149: =G149/Summary!$E$8*100 -> 99.937324 | K149: =Summary!$D$9 -> 16.937449 | L149: =IF(OR(D149="",E149=""),"edge hidden",IF(AND(H149>=D149-0.02,H149<=E149+0.02),"yes","no")) -> edge hidden
A150: 43991 | B150: 10046.65 | D150: 17.0301 | F150: =IF(C150="","",B150/C150) | G150: =MEDIAN(F140:F160) -> 583.79046 | H150: =B150/G150 -> 17.209343 | I150: =B150/Summary!$C$8*100 -> 100.67691 | J150: =G150/Summary!$E$8*100 -> 99.218588 | K150: =Summary!$D$9 -> 16.937449 | L150: =IF(OR(D150="",E150=""),"edge hidden",IF(AND(H150>=D150-0.02,H150<=E150+0.02),"yes","no")) -> edge hidden
A151: 43992 | B151: 10116.15 | D151: 17.0222 | F151: =IF(C151="","",B151/C151) | G151: =MEDIAN(F141:F161) -> 583.79046 | H151: =B151/G151 -> 17.328392 | I151: =B151/Summary!$C$8*100 -> 101.37337 | J151: =G151/Summary!$E$8*100 -> 99.218588 | K151: =Summary!$D$9 -> 16.937449 | L151: =IF(OR(D151="",E151=""),"edge hidden",IF(AND(H151>=D151-0.02,H151<=E151+0.02),"yes","no")) -> edge hidden
A152: 43993 | B152: 9902 | F152: =IF(C152="","",B152/C152) | G152: =MEDIAN(F142:F162) -> 579.71872 | H152: =B152/G152 -> 17.080697 | I152: =B152/Summary!$C$8*100 -> 99.227385 | J152: =G152/Summary!$E$8*100 -> 98.526573 | K152: =Summary!$D$9 -> 16.937449 | L152: =IF(OR(D152="",E152=""),"edge hidden",IF(AND(H152>=D152-0.02,H152<=E152+0.02),"yes","no")) -> edge hidden
A153: 43994 | B153: 9972.9 | F153: =IF(C153="","",B153/C153) | G153: =MEDIAN(F143:F163) -> 578.92386 | H153: =B153/G153 -> 17.226618 | I153: =B153/Summary!$C$8*100 -> 99.93787 | J153: =G153/Summary!$E$8*100 -> 98.391481 | K153: =Summary!$D$9 -> 16.937449 | L153: =IF(OR(D153="",E153=""),"edge hidden",IF(AND(H153>=D153-0.02,H153<=E153+0.02),"yes","no")) -> edge hidden
A154: 43997 | B154: 9813.7 | E154: 17.6482 | F154: =IF(C154="","",B154/C154) | G154: =MEDIAN(F144:F164) -> 574.95769 | H154: =B154/G154 -> 17.06856 | I154: =B154/Summary!$C$8*100 -> 98.342536 | J154: =G154/Summary!$E$8*100 -> 97.717408 | K154: =Summary!$D$9 -> 16.937449 | L154: =IF(OR(D154="",E154=""),"edge hidden",IF(AND(H154>=D154-0.02,H154<=E154+0.02),"yes","no")) -> edge hidden
A155: 43998 | B155: 9914 | E155: 17.7742 | F155: =IF(C155="","",B155/C155) | G155: =MEDIAN(F145:F165) -> 571.07673 | H155: =B155/G155 -> 17.360189 | I155: =B155/Summary!$C$8*100 -> 99.347637 | J155: =G155/Summary!$E$8*100 -> 97.057816 | K155: =Summary!$D$9 -> 16.937449 | L155: =IF(OR(D155="",E155=""),"edge hidden",IF(AND(H155>=D155-0.02,H155<=E155+0.02),"yes","no")) -> edge hidden
A156: 43999 | B156: 9881.15 | E156: 17.7821 | F156: =IF(C156="","",B156/C156) | G156: =MEDIAN(F146:F166) -> 568.80879 | H156: =B156/G156 -> 17.371655 | I156: =B156/Summary!$C$8*100 -> 99.018449 | J156: =G156/Summary!$E$8*100 -> 96.672367 | K156: =Summary!$D$9 -> 16.937449 | L156: =IF(OR(D156="",E156=""),"edge hidden",IF(AND(H156>=D156-0.02,H156<=E156+0.02),"yes","no")) -> edge hidden
A157: 44000 | B157: 10091.65 | C157: 17.4494 | D157: 17.101 | E157: 17.7978 | F157: =IF(C157="","",B157/C157) -> 578.33794 | G157: =MEDIAN(F147:F167) -> 567.04157 | H157: =B157/G157 -> 17.79702 | I157: =B157/Summary!$C$8*100 -> 101.12786 | J157: =G157/Summary!$E$8*100 -> 96.372016 | K157: =Summary!$D$9 -> 16.937449 | L157: =IF(OR(D157="",E157=""),"edge hidden",IF(AND(H157>=D157-0.02,H157<=E157+0.02),"yes","no")) -> yes
A158: 44001 | B158: 10244.4 | C158: 17.6777 | D158: 17.2663 | E158: 18.0891 | F158: =IF(C158="","",B158/C158) -> 579.50978 | G158: =MEDIAN(F148:F168) -> 566.40669 | H158: =B158/G158 -> 18.086651 | I158: =B158/Summary!$C$8*100 -> 102.65856 | J158: =G158/Summary!$E$8*100 -> 96.264116 | K158: =Summary!$D$9 -> 16.937449 | L158: =IF(OR(D158="",E158=""),"edge hidden",IF(AND(H158>=D158-0.02,H158<=E158+0.02),"yes","no")) -> yes
A159: 44004 | B159: 10311.2 | C159: 18.0399 | D159: 17.7624 | E159: 18.3175 | F159: =IF(C159="","",B159/C159) -> 571.57745 | G159: =MEDIAN(F149:F169) -> 565.77182 | H159: =B159/G159 -> 18.225015 | I159: =B159/Summary!$C$8*100 -> 103.32796 | J159: =G159/Summary!$E$8*100 -> 96.156216 | K159: =Summary!$D$9 -> 16.937449 | L159: =IF(OR(D159="",E159=""),"edge hidden",IF(AND(H159>=D159-0.02,H159<=E159+0.02),"yes","no")) -> yes
A160: 44005 | B160: 10471 | C160: 18.0557 | D160: 17.7781 | E160: 18.3332 | F160: =IF(C160="","",B160/C160) -> 579.92767 | G160: =MEDIAN(F150:F170) -> 564.5111 | H160: =B160/G160 -> 18.548794 | I160: =B160/Summary!$C$8*100 -> 104.9293 | J160: =G160/Summary!$E$8*100 -> 95.941948 | K160: =Summary!$D$9 -> 16.937449 | L160: =IF(OR(D160="",E160=""),"edge hidden",IF(AND(H160>=D160-0.02,H160<=E160+0.02),"yes","no")) -> no
A161: 44006 | B161: 10305.3 | C161: 18.1738 | D161: 17.9041 | E161: 18.4435 | F161: =IF(C161="","",B161/C161) -> 567.04157 | G161: =MEDIAN(F151:F171) -> 563.25037 | H161: =B161/G161 -> 18.296126 | I161: =B161/Summary!$C$8*100 -> 103.26883 | J161: =G161/Summary!$E$8*100 -> 95.727681 | K161: =Summary!$D$9 -> 16.937449 | L161: =IF(OR(D161="",E161=""),"edge hidden",IF(AND(H161>=D161-0.02,H161<=E161+0.02),"yes","no")) -> yes
...

Sheet Summary
A1: Nifty 50: price, forward P/E and forward earnings at key dates
A2: Blue = input you can change. Everything else is a formula on the Data sheet. Price = forward EPS x forward P/E, so the three multiples in each row reconcile.
A4: Index base date (input) | B4: 43984 | C4: Early June 2020, when the forward P/E was last at today's level (the circled point on the Bloomberg chart).
A6: Point in time | B6: Date used | C6: Nifty 50 | D6: Fwd P/E | E6: Fwd EPS | F6: Price multiple to latest | G6: EPS multiple to latest | H6: P/E multiple to latest | I6: Price CAGR to latest | J6: EPS CAGR to latest
A7: Start of 2020 (pre-COVID) | B7: =INDEX(Data!$A:$A,MATCH(DATE(2020,1,1),Data!$A:$A,1)) -> 43831 | C7: =INDEX(Data!$B:$B,MATCH($B7,Data!$A:$A,0)) -> 12182.5 | D7: =INDEX(Data!$H:$H,MATCH($B7,Data!$A:$A,0)) -> 18.279702 | E7: =INDEX(Data!$G:$G,MATCH($B7,Data!$A:$A,0)) -> 666.4496 | F7: =$C$9/C7 -> 1.8699159 | G7: =$E$9/E7 -> 2.0181023 | H7: =$D$9/D7 -> 0.9265714 | I7: =IF($B$9-B7<365,"",(C$9/C7)^(365.25/($B$9-B7))-1) -> 0.097301977 | J7: =IF($B$9-B7<365,"",(E$9/E7)^(365.25/($B$9-B7))-1) -> 0.10978754
A8: Index base: early June 2020 | B8: =INDEX(Data!$A:$A,MATCH($B$4,Data!$A:$A,1)) -> 43984 | C8: =INDEX(Data!$B:$B,MATCH($B8,Data!$A:$A,0)) -> 9979.1 | D8: =INDEX(Data!$H:$H,MATCH($B8,Data!$A:$A,0)) -> 16.960062 | E8: =INDEX(Data!$G:$G,MATCH($B8,Data!$A:$A,0)) -> 588.38819 | F8: =$C$9/C8 -> 2.282796 | G8: =$E$9/E8 -> 2.2858437 | H8: =$D$9/D8 -> 0.99866671 | I8: =IF($B$9-B8<365,"",(C$9/C8)^(365.25/($B$9-B8))-1) -> 0.13947355 | J8: =IF($B$9-B8<365,"",(E$9/E8)^(365.25/($B$9-B8))-1) -> 0.13971406
A9: Latest | B9: =MAX(Data!$A$2:$A$1711) -> 46293 | C9: =INDEX(Data!$B:$B,MATCH($B9,Data!$A:$A,0)) -> 22780.25 | D9: =INDEX(Data!$H:$H,MATCH($B9,Data!$A:$A,0)) -> 16.937449 | E9: =INDEX(Data!$G:$G,MATCH($B9,Data!$A:$A,0)) -> 1344.9635 | F9: =$C$9/C9 -> 1 | G9: =$E$9/E9 -> 1 | H9: =$D$9/D9 -> 1 | I9: =IF($B$9-B9<365,"",(C$9/C9)^(365.25/($B$9-B9))-1) | J9: =IF($B$9-B9<365,"",(E$9/E9)^(365.25/($B$9-B9))-1)
A10: COVID low (lowest P/E) | B10: =INDEX(Data!$A:$A,MATCH(MIN(Data!$H$2:$H$1711),Data!$H:$H,0)) -> 43913 | C10: =INDEX(Data!$B:$B,MATCH($B10,Data!$A:$A,0)) -> 7610.25 | D10: =INDEX(Data!$H:$H,MATCH($B10,Data!$A:$A,0)) -> 11.417688 | E10: =INDEX(Data!$G:$G,MATCH($B10,Data!$A:$A,0)) -> 666.53163 | F10: =$C$9/C10 -> 2.9933642 | G10: =$E$9/E10 -> 2.0178539 | H10: =$D$9/D10 -> 1.4834395 | I10: =IF($B$9-B10<365,"",(C$9/C10)^(365.25/($B$9-B10))-1) -> 0.18324448 | J10: =IF($B$9-B10<365,"",(E$9/E10)^(365.25/($B$9-B10))-1) -> 0.11375669
A11: Peak forward P/E | B11: =INDEX(Data!$A:$A,MATCH(MAX(Data!$H$2:$H$1711),Data!$H:$H,0)) -> 44487 | C11: =INDEX(Data!$B:$B,MATCH($B11,Data!$A:$A,0)) -> 18477.05 | D11: =INDEX(Data!$H:$H,MATCH($B11,Data!$A:$A,0)) -> 22.978478 | E11: =INDEX(Data!$G:$G,MATCH($B11,Data!$A:$A,0)) -> 804.10243 | F11: =$C$9/C11 -> 1.2328943 | G11: =$E$9/E11 -> 1.672627 | H11: =$D$9/D11 -> 0.73710056 | I11: =IF($B$9-B11<365,"",(C$9/C11)^(365.25/($B$9-B11))-1) -> 0.043251635 | J11: =IF($B$9-B11<365,"",(E$9/E11)^(365.25/($B$9-B11))-1) -> 0.10963667
A12: Mid-2022 low | B12: =INDEX(Data!$A:$A,MATCH(MIN(Data!$H$600:$H$700),Data!$H:$H,0)) -> 44729 | C12: =INDEX(Data!$B:$B,MATCH($B12,Data!$A:$A,0)) -> 15293.5 | D12: =INDEX(Data!$H:$H,MATCH($B12,Data!$A:$A,0)) -> 17.032179 | E12: =INDEX(Data!$G:$G,MATCH($B12,Data!$A:$A,0)) -> 897.91799 | F12: =$C$9/C12 -> 1.489538 | G12: =$E$9/E12 -> 1.4978689 | H12: =$D$9/D12 -> 0.99443816 | I12: =IF($B$9-B12<365,"",(C$9/C12)^(365.25/($B$9-B12))-1) -> 0.097523289 | J12: =IF($B$9-B12<365,"",(E$9/E12)^(365.25/($B$9-B12))-1) -> 0.09895376
A13: Nifty all-time closing high | B13: =INDEX(Data!$A:$A,MATCH(MAX(Data!$B$2:$B$1711),Data!$B:$B,0)) -> 46024 | C13: =INDEX(Data!$B:$B,MATCH($B13,Data!$A:$A,0)) -> 26328.55 | D13: =INDEX(Data!$H:$H,MATCH($B13,Data!$A:$A,0)) -> 21.311237 | E13: =INDEX(Data!$G:$G,MATCH($B13,Data!$A:$A,0)) -> 1235.4304 | F13: =$C$9/C13 -> 0.86522995 | G13: =$E$9/E13 -> 1.0886598 | H13: =$D$9/D13 -> 0.79476611 | I13: =IF($B$9-B13<365,"",(C$9/C13)^(365.25/($B$9-B13))-1) | J13: =IF($B$9-B13<365,"",(E$9/E13)^(365.25/($B$9-B13))-1)
A14: End of 2025 | B14: =INDEX(Data!$A:$A,MATCH(DATE(2025,12,31),Data!$A:$A,1)) -> 46022 | C14: =INDEX(Data!$B:$B,MATCH($B14,Data!$A:$A,0)) -> 26129.6 | D14: =INDEX(Data!$H:$H,MATCH($B14,Data!$A:$A,0)) -> 21.17856 | E14: =INDEX(Data!$G:$G,MATCH($B14,Data!$A:$A,0)) -> 1233.7761 | F14: =$C$9/C14 -> 0.87181779 | G14: =$E$9/E14 -> 1.0901196 | H14: =$D$9/D14 -> 0.79974507 | I14: =IF($B$9-B14<365,"",(C$9/C14)^(365.25/($B$9-B14))-1) | J14: =IF($B$9-B14<365,"",(E$9/E14)^(365.25/($B$9-B14))-1)
A16: Check: price multiple = EPS multiple x P/E multiple (base row) | B16: =ROUND(F8-G8*H8,6) -> 0 | C16: =IF(ABS(B16)<0.0001,"reconciles","CHECK") -> reconciles
A18: Latest forward P/E vs earlier lows (x)
A19: Latest minus mid-2022 low | B19: =D9-D12 -> -0.094730262 | C19: Differences this small are inside the digitisation error (about ±0.4x), so treat "cheapest since 2020" as Bloomberg's call on its own data.
A20: Latest minus March-2023 low | B20: =D9-MIN(Data!$H$840:$H$880) -> -0.21613439
A22: Share of days where the rebuilt P/E sits inside the chart band | B22: =COUNTIF(Data!$L$2:$L$1711,"yes")/(COUNTIF(Data!$L$2:$L$1711,"yes")+COUNTIF(Data!$L$2:$L$1711,"no")) -> 0.86017699

Sheet Validation
A1: A. Digitised forward P/E vs readings published with a Bloomberg attribution
A2: Date | B2: Published fwd P/E | C2: Our rebuilt fwd P/E | D2: Difference | E2: Attribution | F2: Source
A3: 43895 | B3: 16.6 | C3: =INDEX(Data!$H:$H,MATCH(A3,Data!$A:$A,1)) -> 16.238237 | D3: =C3-B3 -> -0.36176309 | E3: Bloomberg data, via Financial Express | F3: https://prelaunch.financialexpress.com/market/niftys-premium-valuations-take-hit-slip-below-5-yr-average-1890411/
A4: 44487 | B4: 22.74 | C4: =INDEX(Data!$H:$H,MATCH(A4,Data!$A:$A,1)) -> 22.978478 | D4: =C4-B4 -> 0.23847794 | E4: Bloomberg data, via Financial Express | F4: Financial Express (18 May 2022 report citing the 18 Oct 2021 peak)
A5: 44699 | B5: 17.93 | C5: =INDEX(Data!$H:$H,MATCH(A5,Data!$A:$A,1)) -> 18.267927 | D5: =C5-B5 -> 0.33792666 | E5: Bloomberg data, via Financial Express | F5: Financial Express (18 May 2022)
A6: 44725 | B6: 17.4 | C6: =INDEX(Data!$H:$H,MATCH(A6,Data!$A:$A,1)) -> 17.598892 | D6: =C6-B6 -> 0.19889249 | E6: Bloomberg data, via Financial Express | F6: Financial Express (13 Jun 2022)
A7: 45539 | B7: 21.05 | C7: =INDEX(Data!$H:$H,MATCH(A7,Data!$A:$A,1)) -> 20.800593 | D7: =C7-B7 -> -0.24940722 | E7: Bloomberg data, via Moneycontrol | F7: Moneycontrol (4 Sep 2024)
A8: 45561 | B8: 21.4 | C8: =INDEX(Data!$H:$H,MATCH(A8,Data!$A:$A,1)) -> 21.5102 | D8: =C8-B8 -> 0.11019996 | E8: Bloomberg data, via Paisa Journal | F8: Paisa Journal (26 Sep 2024)
A9: 46277 | B9: 17.6 | C9: =INDEX(Data!$H:$H,MATCH(A9,Data!$A:$A,1)) -> 17.4848 | D9: =C9-B9 -> -0.1152 | E9: Bloomberg, via ThePrint (approximate) | F9: ThePrint republishing Bloomberg (12 Sep 2026)
A10: Mean absolute difference | D10: =SUMPRODUCT(ABS(D3:D9))/COUNT(D3:D9) -> 0.23026676
A11: Excluded: Mint (11 Sep 2020) quoted "Bloomberg data" at 25.5x for 10 Sep 2020; the Bloomberg chart used here shows about 20x that day, so Mint was quoting a different Bloomberg field. Brokerage series (Motilal Oswal, Jefferies, LSEG) run on different earnings estimates and differ by 0.5-2x; they are not used for this check.
A14: B. Actual Nifty 50 EPS as reported by Motilal Oswal (fiscal years ending March)
A15: Fiscal year | B15: EPS (₹) | C15: YoY growth | D15: Status | E15: Note | F15: Source
A16: FY21 | B16: 539 | D16: actual | E16: +14.2% YoY as reported | F16: Mint (Jun 2021), MOFSL
A17: FY22 | B17: 737 | C17: =B17/B16-1 -> 0.36734694 | D17: actual (interim) | E17: From the 4QFY22 review; final print not found | F17: Zee Business / PTI (May 2022), MOFSL
A18: FY23 | B18: 806 | C18: =B18/B17-1 -> 0.093622795 | D18: actual | F18: MOFSL via BQ Prime (Jul 2023)
A19: FY24 | B19: 1005 | C19: =B19/B18-1 -> 0.24689826 | D19: actual | E19: +24% YoY as reported | F19: Motilal Oswal (31 May 2024)
A20: FY25 | B20: 1013 | C20: =B20/B19-1 -> 0.007960199 | D20: actual | E20: +1% YoY as reported | F20: Motilal Oswal (Jun 2025)
A21: FY26 | B21: 1065 | C21: =B21/B20-1 -> 0.051332675 | D21: actual | E21: +5% YoY as reported | F21: MOFSL via The Adviser Times / ET Now (Jun 2026)
A22: FY27E | B22: 1232 | C22: =B22/B21-1 -> 0.15680751 | D22: estimate | E22: MOFSL Aug 2026; consensus was 1,357 a year earlier (JM Financial / Bloomberg) | F22: Motilal Oswal (Aug 2026)
A23: FY28E | B23: 1425 | C23: =B23/B22-1 -> 0.15665584 | D23: estimate | F23: Motilal Oswal (Aug 2026)
A25: FY21 to FY26 actual EPS multiple | B25: =B21/B16 -> 1.9758813
A26: FY21 to FY26 actual EPS CAGR | B26: =(B21/B16)^(1/5)-1 -> 0.14591438
A27: Forward EPS multiple, base date to latest (from Summary) | B27: =Summary!G8 -> 2.2858437
A28: FY20 actual EPS is not cleanly reported: MOFSL's FY21 figure implies about ₹472, other houses put FY20 near ₹400, because constituents and consolidation differ. So the comparison starts at FY21.
A30: C. Consensus FY27 EPS and the 12-month forward blend
A31: Consensus FY27 EPS, mid-2025 (₹) | B31: 1357 | F31: JM Financial Nifty50 Analyser (Bloomberg consensus), via Moneycontrol / 5paisa, 3 Jun 2026
A32: Consensus FY27 EPS, May 2026 (₹) | B32: 1235 | F32: Same source
A33: Cut in consensus FY27 EPS | B33: =B32/B31-1 -> -0.0899042
A34: 50/50 blend of MOFSL FY27E and FY28E (₹): what a 12-month forward figure looks like in late September | B34: =0.5*B22+0.5*B23 -> 1328.5
A35: Latest implied forward EPS on the Data sheet (₹) | B35: =Summary!E9 -> 1344.9635
A36: Actual EPS roughly doubled FY21-FY26; the rest of the 2.3x rise in forward EPS is forecast, since the late-September 12-month window is about half FY27 and half FY28.

Sheet Method & Sources
A1: How this workbook was built
A2: 1. Nifty 50 daily closes (31 Oct 2019 to 28 Sep 2026) come from Yahoo Finance (^NSEI, NSE data). Two people-independent transcriptions of every page were diffed; all 1,728 rows matched exactly, and every month-end close matches Yahoo's monthly table.
A3: 2. The 12-month forward P/E is Bloomberg's series from the chart "Indian Stocks Cheapest Since 2020 by Forward P/E" (Source: Bloomberg). Bloomberg does not publish this series openly, so it was digitised from the chart image (4096 x 2223 px).
A4: Y scale: seven gridlines (12 to 24) fitted linearly, largest residual 0.003x. X scale: seven year ticks fitted linearly, largest residual 0.24 days; the COVID low lands on 22-23 Mar 2020.
A5: For each trading day the top and bottom edge of the orange stroke are read. Half the stroke width (4.25 px, about 0.03x) is taken off each edge, which leaves the range the true value must lie in.
A6: 3. Implied forward EPS = Nifty close / digitised forward P/E, then a centred 21-trading-day median (forward EPS moves slowly; the median removes reading noise).
A7: 4. Rebuilt forward P/E = Nifty close / smoothed forward EPS. This puts back the real day-to-day moves from actual prices. It sits inside the chart band on about 86% of days; when outside, the median miss is 0.03x and the worst is 0.26x.
A8: 5. Against seven readings published with a Bloomberg attribution (Validation sheet), the rebuilt series differs by -0.36x to +0.34x. Treat every P/E here as accurate to about ±0.4x.
A9: 6. The last Bloomberg point is 28 Sep 2026 (the final downward tick of the line, the day Nifty fell 1.6%). Nothing is extrapolated past the chart.
A10: 7. Indices: price and forward EPS are rebased to 100 on the base date on the Summary sheet (2 Jun 2020). Change that date and the chart and table update.
A12: What the numbers are, and what they are not
A13: Forward EPS is analysts' consensus estimate of the next 12 months' earnings, as Bloomberg aggregates it. It is not reported profit. As a cross-check, Motilal Oswal's tally of actual Nifty EPS rose from ₹539 (FY21) to ₹1,065 (FY26), about 2x, in line with the forward series.
... A25: Business Today / PTI, Sep 2026 (FPI net equity outflow of about ₹2.45 lakh crore in calendar 2026 to date).
