Workbook

Sheet Chart
B2: Until 2019, the Nifty rose because investors paid more for each rupee of profit. Since then, profits have done the lifting.
B3: Over ten years the Nifty grew 2.6 times and the profit behind it about 2.7 to 2.8 times, after adjusting for NSE's 2021 change in how profit is counted. So investors now pay the same or a little less for each rupee of profit as they did in 2016.
B4: On 31 Mar 2021 NSE began counting subsidiaries' profits as well as the parent company's (consolidated instead of standalone earnings), which cut its P/E from 40.4x to 33.2x overnight. Lighter lines show the old method.
B6: ="Nifty 50 "&TEXT(Summary!C15,"#,##0")&" → "&TEXT(Summary!C22,"#,##0")&" ("&TEXT(Summary!I15,"0.0")&"x)" -> Nifty 50 8,611 → 22,780 (2.6x) | I6: ="Profit per unit ₹"&TEXT(Summary!F15,"#,##0")&"* → ₹"&TEXT(Summary!F22,"#,##0")&" ("&TEXT(Summary!D34,"0.0")&"x to "&TEXT(Summary!C34,"0.0")&"x)" -> Profit per unit ₹368* → ₹1,183 (2.7x to 2.8x) | Q6: ="P/E "&TEXT(Summary!D15,"0.0")&"x* → "&TEXT(Summary!D22,"0.0")&"x ("&TEXT(Summary!D36,"+0%;-0%")&" to "&TEXT(Summary!C36,"+0%;-0%")&")" -> P/E 23.4x* → 19.3x (-1% to -6%)
B53: Source: NSE Indices (Nifty 50 P/E, trailing four quarters, month-end; via Downstox, checked against NSE Index Dashboards), Yahoo Finance (Nifty 50 daily closes). Profit per unit = Nifty close ÷ NSE P/E. Latest reading 28 Sep 2026.
B54: * Old method (parent-company profit only). Changes in brackets are like-for-like: pre-2021 profit multiplied by 1.14 (Bloomberg's 10-year average gap) to 1.205 (the gap on NSE's switch day). A lower 2019 estimate of 1.05 (PrimeInvestor) would put the profit multiple at 3.1x. Motilal Oswal's separate count of Nifty EPS: ₹393 (FY16) to ₹1,065 (FY26), 2.7x.
B56: 1 Finance | SEBI Registered Investment Advisor. This content is for information and educational purposes only. Please consult a Qualified Financial Advisor before making investment decisions.

Sheet Monthly
A1: Month-end (last trading day) | B1: Nifty 50 close | C1: NSE P/E as published | D1: Earnings basis | E1: Trailing EPS as published (close / P/E), ₹ | F1: Trailing EPS, like-for-like (pre-2021 x ratio), ₹ | G1: P/E, like-for-like (pre-2021 / ratio) | H1: EPS growth over 12 months, like-for-like | I1: Note
A2: 42643 | B2: =INDEX(Daily!$B:$B,MATCH(A2,Daily!$A:$A,0)) -> 8611.15 | C2: 23.4 | D2: standalone | E2: =B2/C2 -> 367.99786 | F2: =IF(D2="standalone",E2*Summary!$B$11,E2) -> 443.4762 | G2: =B2/F2 -> 19.417389
A3: 42671 | B3: =INDEX(Daily!$B:$B,MATCH(A3,Daily!$A:$A,0)) -> 8638 | C3: 23.3 | D3: standalone | E3: =B3/C3 -> 370.72961 | F3: =IF(D3="standalone",E3*Summary!$B$11,E3) -> 446.76825 | G3: =B3/F3 -> 19.334409
A4: 42704 | B4: =INDEX(Daily!$B:$B,MATCH(A4,Daily!$A:$A,0)) -> 8224.5 | C4: 21.6 | D4: standalone | E4: =B4/C4 -> 380.76389 | F4: =IF(D4="standalone",E4*Summary!$B$11,E4) -> 458.86061 | G4: =B4/F4 -> 17.923744
A5: 42734 | B5: =INDEX(Daily!$B:$B,MATCH(A5,Daily!$A:$A,0)) -> 8185.8 | C5: 21.93 | D5: standalone | E5: =B5/C5 -> 373.26949 | F5: =IF(D5="standalone",E5*Summary!$B$11,E5) -> 449.82907 | G5: =B5/F5 -> 18.197579
A6: 42766 | B6: =INDEX(Daily!$B:$B,MATCH(A6,Daily!$A:$A,0)) -> 8561.3 | C6: 22.9 | D6: standalone | E6: =B6/C6 -> 373.8559 | F6: =IF(D6="standalone",E6*Summary!$B$11,E6) -> 450.53575 | G6: =B6/F6 -> 19.002488
A7: 42794 | B7: =INDEX(Daily!$B:$B,MATCH(A7,Daily!$A:$A,0)) -> 8879.6 | C7: 23.1 | D7: standalone | E7: =B7/C7 -> 384.39827 | F7: =IF(D7="standalone",E7*Summary!$B$11,E7) -> 463.24042 | G7: =B7/F7 -> 19.168448
A8: 42825 | B8: =INDEX(Daily!$B:$B,MATCH(A8,Daily!$A:$A,0)) -> 9173.75 | C8: 23.3 | D8: standalone | E8: =B8/C8 -> 393.72318 | F8: =IF(D8="standalone",E8*Summary!$B$11,E8) -> 474.47791 | G8: =B8/F8 -> 19.334409
A9: 42853 | B9: =INDEX(Daily!$B:$B,MATCH(A9,Daily!$A:$A,0)) -> 9304.05 | C9: 23.6 | D9: standalone | E9: =B9/C9 -> 394.23941 | F9: =IF(D9="standalone",E9*Summary!$B$11,E9) -> 475.10002 | G9: =B9/F9 -> 19.58335
A10: 42886 | B10: =INDEX(Daily!$B:$B,MATCH(A10,Daily!$A:$A,0)) -> 9621.25 | C10: 24.4 | D10: standalone | E10: =B10/C10 -> 394.31352 | F10: =IF(D10="standalone",E10*Summary!$B$11,E10) -> 475.18934 | G10: =B10/F10 -> 20.247192
A11: 42916 | B11: =INDEX(Daily!$B:$B,MATCH(A11,Daily!$A:$A,0)) -> 9520.9 | C11: 24.2 | D11: standalone | E11: =B11/C11 -> 393.42562 | F11: =IF(D11="standalone",E11*Summary!$B$11,E11) -> 474.11933 | G11: =B11/F11 -> 20.081232
A12: 42947 | B12: =INDEX(Daily!$B:$B,MATCH(A12,Daily!$A:$A,0)) -> 10077.1 | C12: 25.7 | D12: standalone | E12: =B12/C12 -> 392.10506 | F12: =IF(D12="standalone",E12*Summary!$B$11,E12) -> 472.52791 | G12: =B12/F12 -> 21.325936
A13: 42978 | B13: =INDEX(Daily!$B:$B,MATCH(A13,Daily!$A:$A,0)) -> 9917.9 | C13: 25.6 | D13: standalone | E13: =B13/C13 -> 387.41797 | F13: =IF(D13="standalone",E13*Summary!$B$11,E13) -> 466.87947 | G13: =B13/F13 -> 21.242956
A14: 43007 | B14: =INDEX(Daily!$B:$B,MATCH(A14,Daily!$A:$A,0)) -> 9788.6 | C14: 25.4 | D14: standalone | E14: =B14/C14 -> 385.37795 | F14: =IF(D14="standalone",E14*Summary!$B$11,E14) -> 464.42104 | G14: =B14/F14 -> 21.076995 | H14: =F14/F2-1 -> 0.047228778
A15: 43039 | B15: =INDEX(Daily!$B:$B,MATCH(A15,Daily!$A:$A,0)) -> 10335.3 | C15: 26.4 | D15: standalone | E15: =B15/C15 -> 391.48864 | F15: =IF(D15="standalone",E15*Summary!$B$11,E15) -> 471.78506 | G15: =B15/F15 -> 21.906798 | H15: =F15/F3-1 -> 0.055995048
A16: 43069 | B16: =INDEX(Daily!$B:$B,MATCH(A16,Daily!$A:$A,0)) -> 10226.55 | C16: 26.2 | D16: standalone | E16: =B16/C16 -> 390.32634 | F16: =IF(D16="standalone",E16*Summary!$B$11,E16) -> 470.38436 | G16: =B16/F16 -> 21.740838 | H16: =F16/F4-1 -> 0.025113849
A17: 43098 | B17: =INDEX(Daily!$B:$B,MATCH(A17,Daily!$A:$A,0)) -> 10530.7 | C17: 26.92 | D17: standalone | E17: =B17/C17 -> 391.18499 | F17: =IF(D17="standalone",E17*Summary!$B$11,E17) -> 471.41913 | G17: =B17/F17 -> 22.338296 | H17: =F17/F5-1 -> 0.04799615
A18: 43131 | B18: =INDEX(Daily!$B:$B,MATCH(A18,Daily!$A:$A,0)) -> 11027.7 | C18: 27.5 | D18: standalone | E18: =B18/C18 -> 401.00727 | F18: =IF(D18="standalone",E18*Summary!$B$11,E18) -> 483.25602 | G18: =B18/F18 -> 22.819581 | H18: =F18/F6-1 -> 0.072625249
A19: 43159 | B19: =INDEX(Daily!$B:$B,MATCH(A19,Daily!$A:$A,0)) -> 10492.85 | C19: 25.7 | D19: standalone | E19: =B19/C19 -> 408.2821 | F19: =IF(D19="standalone",E19*Summary!$B$11,E19) -> 492.02295 | G19: =B19/F19 -> 21.325936 | H19: =F19/F7-1 -> 0.062133039
A20: 43187 | B20: =INDEX(Daily!$B:$B,MATCH(A20,Daily!$A:$A,0)) -> 10113.7 | C20: 24.7 | D20: standalone | E20: =B20/C20 -> 409.46154 | F20: =IF(D20="standalone",E20*Summary!$B$11,E20) -> 493.4443 | G20: =B20/F20 -> 20.496133 | H20: =F20/F8-1 -> 0.039973168
A21: 43220 | B21: =INDEX(Daily!$B:$B,MATCH(A21,Daily!$A:$A,0)) -> 10739.35 | C21: 26.7 | D21: standalone | E21: =B21/C21 -> 402.22285 | F21: =IF(D21="standalone",E21*Summary!$B$11,E21) -> 484.72091 | G21: =B21/F21 -> 22.155739 | H21: =F21/F9-1 -> 0.020250233
A22: 43251 | B22: =INDEX(Daily!$B:$B,MATCH(A22,Daily!$A:$A,0)) -> 10736.15 | C22: 27.2 | D22: standalone | E22: =B22/C22 -> 394.7114 | F22: =IF(D22="standalone",E22*Summary!$B$11,E22) -> 475.66882 | G22: =B22/F22 -> 22.570641 | H22: =F22/F10-1 -> 0.0010090257
A23: 43280 | B23: =INDEX(Daily!$B:$B,MATCH(A23,Daily!$A:$A,0)) -> 10714.3 | C23: 25.9 | D23: standalone | E23: =B23/C23 -> 413.67954 | F23: =IF(D23="standalone",E23*Summary!$B$11,E23) -> 498.52743 | G23: =B23/F23 -> 21.491897 | H23: =F23/F11-1 -> 0.05148093
A24: 43312 | B24: =INDEX(Daily!$B:$B,MATCH(A24,Daily!$A:$A,0)) -> 11356.5 | C24: 28.2 | D24: standalone | E24: =B24/C24 -> 402.71277 | F24: =IF(D24="standalone",E24*Summary!$B$11,E24) -> 485.31132 | G24: =B24/F24 -> 23.400443 | H24: =F24/F12-1 -> 0.027053228
A25: 43343 | B25: =INDEX(Daily!$B:$B,MATCH(A25,Daily!$A:$A,0)) -> 11680.5 | C25: 28.4 | D25: standalone | E25: =B25/C25 -> 411.28521 | F25: =IF(D25="standalone",E25*Summary!$B$11,E25) -> 495.64202 | G25: =B25/F25 -> 23.566404 | H25: =F25/F13-1 -> 0.061605925
... A55: 44253 | B55: =INDEX(Daily!$B:$B,MATCH(A55,Daily!$A:$A,0)) -> 14529.15 | C55: 39.6 | D55: standalone | E55: =B55/C55 -> 366.89773 | F55: =IF(D55="standalone",E55*Summary!$B$11,E55) -> 442.15042 | G55: =B55/F55 -> 32.860197 | H55: =F55/F43-1 -> -0.164783
A56: 44286 | B56: =INDEX(Daily!$B:$B,MATCH(A56,Daily!$A:$A,0)) -> 14690.7 | C56: 33.2 | D56: consolidated | E56: =B56/C56 -> 442.49096 | F56: =IF(D56="standalone",E56*Summary!$B$11,E56) -> 442.49096 | G56: =B56/F56 -> 33.2 | H56: =F56/F44-1 -> -0.17149277 | I56: First consolidated reading (31 Mar 2021). NSE P/E was 40.43 the day before on standalone earnings; the index barely moved.
A57: 44316 | B57: =INDEX(Daily!$B:$B,MATCH(A57,Daily!$A:$A,0)) -> 14631.1 | C57: 32.2 | D57: consolidated | E57: =B57/C57 -> 454.38199 | F57: =IF(D57="standalone",E57*Summary!$B$11,E57) -> 454.38199 | G57: =B57/F57 -> 32.2 | H57: =F57/F45-1 -> -0.14341277
A58: 44347 | B58: =INDEX(Daily!$B:$B,MATCH(A58,Daily!$A:$A,0)) -> 15582.8 | C58: 29.2 | D58: consolidated | E58: =B58/C58 -> 533.65753 | F58: =IF(D58="standalone",E58*Summary!$B$11,E58) -> 533.65753 | G58: =B58/F58 -> 29.2 | H58: =F58/F46-1 -> 0.035396123
A59: 44377 | B59: =INDEX(Daily!$B:$B,MATCH(A59,Daily!$A:$A,0)) -> 15721.5 | C59: 28.3 | D59: consolidated | E59: =B59/C59 -> 555.53004 | F59: =IF(D59="standalone",E59*Summary!$B$11,E59) -> 555.53004 | G59: =B59/F59 -> 28.3 | H59: =F59/F47-1 -> 0.1768267
A60: 44407 | B60: =INDEX(Daily!$B:$B,MATCH(A60,Daily!$A:$A,0)) -> 15763.05 | C60: 27 | D60: consolidated | E60: =B60/C60 -> 583.81667 | F60: =IF(D60="standalone",E60*Summary!$B$11,E60) -> 583.81667 | G60: =B60/F60 -> 27 | H60: =F60/F48-1 -> 0.32122098
A61: 44439 | B61: =INDEX(Daily!$B:$B,MATCH(A61,Daily!$A:$A,0)) -> 17132.2 | C61: 26.3 | D61: consolidated | E61: =B61/C61 -> 651.41445 | F61: =IF(D61="standalone",E61*Summary!$B$11,E61) -> 651.41445 | G61: =B61/F61 -> 26.3 | H61: =F61/F49-1 -> 0.53322714
A62: 44469 | B62: =INDEX(Daily!$B:$B,MATCH(A62,Daily!$A:$A,0)) -> 17618.15 | C62: 27 | D62: consolidated | E62: =B62/C62 -> 652.52407 | F62: =IF(D62="standalone",E62*Summary!$B$11,E62) -> 652.52407 | G62: =B62/F62 -> 27 | H62: =F62/F50-1 -> 0.57420519
A63: 44498 | B63: =INDEX(Daily!$B:$B,MATCH(A63,Daily!$A:$A,0)) -> 17671.65 | C63: 25.7 | D63: consolidated | E63: =B63/C63 -> 687.61284 | F63: =IF(D63="standalone",E63*Summary!$B$11,E63) -> 687.61284 | G63: =B63/F63 -> 25.7 | H63: =F63/F51-1 -> 0.56338926
A64: 44530 | B64: =INDEX(Daily!$B:$B,MATCH(A64,Daily!$A:$A,0)) -> 16983.2 | C64: 23.4 | D64: consolidated | E64: =B64/C64 -> 725.77778 | F64: =IF(D64="standalone",E64*Summary!$B$11,E64) -> 725.77778 | G64: =B64/F64 -> 23.4 | H64: =F64/F52-1 -> 0.65783783
A65: 44561 | B65: =INDEX(Daily!$B:$B,MATCH(A65,Daily!$A:$A,0)) -> 17354.05 | C65: 24.11 | D65: consolidated | E65: =B65/C65 -> 719.7864 | F65: =IF(D65="standalone",E65*Summary!$B$11,E65) -> 719.7864 | G65: =B65/F65 -> 24.11 | H65: =F65/F53-1 -> 0.64253043
A66: 44592 | B66: =INDEX(Daily!$B:$B,MATCH(A66,Daily!$A:$A,0)) -> 17339.85 | C66: 23.4 | D66: consolidated | E66: =B66/C66 -> 741.01923 | F66: =IF(D66="standalone",E66*Summary!$B$11,E66) -> 741.01923 | G66: =B66/F66 -> 23.4 | H66: =F66/F54-1 -> 0.65060495
A67: 44620 | B67: =INDEX(Daily!$B:$B,MATCH(A67,Daily!$A:$A,0)) -> 16793.9 | C67: 21.6 | D67: consolidated | E67: =B67/C67 -> 777.49537 | F67: =IF(D67="standalone",E67*Summary!$B$11,E67) -> 777.49537 | G67: =B67/F67 -> 21.6 | H67: =F67/F55-1 -> 0.75844087
A68: 44651 | B68: =INDEX(Daily!$B:$B,MATCH(A68,Daily!$A:$A,0)) -> 17464.75 | C68: 22.9 | D68: consolidated | E68: =B68/C68 -> 762.65284 | F68: =IF(D68="standalone",E68*Summary!$B$11,E68) -> 762.65284 | G68: =B68/F68 -> 22.9 | H68: =F68/F56-1 -> 0.72354444
... A121: 46265 | B121: =INDEX(Daily!$B:$B,MATCH(A121,Daily!$A:$A,0)) -> 24080.4 | C121: 20.4 | D121: consolidated | E121: =B121/C121 -> 1180.4118 | F121: =IF(D121="standalone",E121*Summary!$B$11,E121) -> 1180.4118 | G121: =B121/F121 -> 20.4 | H121: =F121/F109-1 -> 0.038973627
...

Sheet Daily
A1: Date | B1: Nifty 50 close | C1: Note
A2: 42614 | B2: 8774.65
A3: 42615 | B3: 8809.65
A4: 42619 | B4: 8943
A5: 42620 | B5: 8917.95
A6: 42621 | B6: 8952.5
A7: 42622 | B7: 8866.7
A8: 42625 | B8: 8715.6
A9: 42627 | B9: 8726.6
A10: 42628 | B10: 8742.55
A11: 42629 | B11: 8779.85
A12: 42632 | B12: 8808.4
A13: 42633 | B13: 8775.9
... A634: 43552 | B634: 11570
A635: 43553 | B635: 11623.9 | C635: Missing from Yahoo's daily table; value is Yahoo's March 2019 monthly close.
A636: 43556 | B636: 11669.15
A637: 43557 | B637: 11713.2
A638: 43558 | B638: 11643.95
A639: 43559 | B639: 11598
A640: 43560 | B640: 11665.95
A641: 43563 | B641: 11604.5
A642: 43564 | B642: 11671.95
A643: 43565 | B643: 11584.3
A644: 43566 | B644: 11596.7
A645: 43567 | B645: 11643.45
A646: 43570 | B646: 11690.35
A647: 43571 | B647: 11787.15
... A2485: 46293 | B2485: 22780.25

Sheet Summary
A1: Nifty 50 over ten years: price, NSE P/E and earnings
A2: Blue = input. Everything else is a formula on the Monthly and Daily sheets. Price = earnings x P/E, so each row reconciles.
A4: NSE's switch from standalone to consolidated earnings
A5: Nifty close, 30 Mar 2021 (last standalone day) | B5: 14845.1
A6: NSE P/E that day, standalone earnings | B6: 40.43
A7: Nifty close, 31 Mar 2021 (first consolidated day) | B7: 14690.7
A8: NSE P/E that day, consolidated earnings | B8: 33.2
A9: Consolidated / standalone earnings at the switch | B9: =(B7/B8)/(B5/B6) -> 1.2051054
A10: Consolidated / standalone, Bloomberg 10-year average (input) | B10: 1.14 | C10: The Hindu BusinessLine, Mar 2021: "on the average ... 14 per cent higher"
A11: Ratio used for the like-for-like columns (input) | B11: =B9 -> 1.2051054 | C11: Default: the switch-day ratio. Type 1.14 (or anything else) to see how the like-for-like columns move.
A12: Low estimate, PrimeInvestor Dec 2019 (input) | B12: 1.05 | C12: PrimeInvestor: consolidated earnings "about 5 per cent higher than the standalone earnings"
A14: Point in time | B14: Month-end | C14: Nifty 50 | D14: NSE P/E as published | E14: Basis | F14: EPS as published (₹) | G14: EPS like-for-like (₹) | H14: P/E like-for-like | I14: Price multiple to latest | J14: EPS multiple to latest (like-for-like) | K14: P/E multiple to latest (like-for-like)
A15: Ten years ago | B15: =INDEX(Monthly!$A:$A,2) -> 42643 | C15: =INDEX(Monthly!$B:$B,MATCH($B15,Monthly!$A:$A,0)) -> 8611.15 | D15: =INDEX(Monthly!$C:$C,MATCH($B15,Monthly!$A:$A,0)) -> 23.4 | E15: =INDEX(Monthly!$D:$D,MATCH($B15,Monthly!$A:$A,0)) -> standalone | F15: =INDEX(Monthly!$E:$E,MATCH($B15,Monthly!$A:$A,0)) -> 367.99786 | G15: =INDEX(Monthly!$F:$F,MATCH($B15,Monthly!$A:$A,0)) -> 443.4762 | H15: =INDEX(Monthly!$G:$G,MATCH($B15,Monthly!$A:$A,0)) -> 19.417389 | I15: =$C$22/C15 -> 2.6454364 | J15: =$G$22/G15 -> 2.6670545 | K15: =$H$22/H15 -> 0.99189442
A16: End of 2019 (before COVID) | B16: =INDEX(Monthly!$A:$A,MATCH(DATE(2019,12,31),Monthly!$A:$A,1)) -> 43830 | C16: =INDEX(Monthly!$B:$B,MATCH($B16,Monthly!$A:$A,0)) -> 12168.45 | D16: =INDEX(Monthly!$C:$C,MATCH($B16,Monthly!$A:$A,0)) -> 28.3 | E16: =INDEX(Monthly!$D:$D,MATCH($B16,Monthly!$A:$A,0)) -> standalone | F16: =INDEX(Monthly!$E:$E,MATCH($B16,Monthly!$A:$A,0)) -> 429.98057 | G16: =INDEX(Monthly!$F:$F,MATCH($B16,Monthly!$A:$A,0)) -> 518.17189 | H16: =INDEX(Monthly!$G:$G,MATCH($B16,Monthly!$A:$A,0)) -> 23.483424 | I16: =$C$22/C16 -> 1.8720749 | J16: =$G$22/G16 -> 2.2825923 | K16: =$H$22/H16 -> 0.82015298
A17: March 2020 (COVID crash) | B17: =INDEX(Monthly!$A:$A,MATCH(DATE(2020,3,31),Monthly!$A:$A,1)) -> 43921 | C17: =INDEX(Monthly!$B:$B,MATCH($B17,Monthly!$A:$A,0)) -> 8597.75 | D17: =INDEX(Monthly!$C:$C,MATCH($B17,Monthly!$A:$A,0)) -> 19.4 | E17: =INDEX(Monthly!$D:$D,MATCH($B17,Monthly!$A:$A,0)) -> standalone | F17: =INDEX(Monthly!$E:$E,MATCH($B17,Monthly!$A:$A,0)) -> 443.18299 | G17: =INDEX(Monthly!$F:$F,MATCH($B17,Monthly!$A:$A,0)) -> 534.0822 | H17: =INDEX(Monthly!$G:$G,MATCH($B17,Monthly!$A:$A,0)) -> 16.098177 | I17: =$C$22/C17 -> 2.6495595 | J17: =$G$22/G17 -> 2.2145939 | K17: =$H$22/H17 -> 1.1964087
A18: Feb 2021 (last standalone month-end) | B18: =INDEX(Monthly!$A:$A,MATCH(DATE(2021,2,28),Monthly!$A:$A,1)) -> 44253 | C18: =INDEX(Monthly!$B:$B,MATCH($B18,Monthly!$A:$A,0)) -> 14529.15 | D18: =INDEX(Monthly!$C:$C,MATCH($B18,Monthly!$A:$A,0)) -> 39.6 | E18: =INDEX(Monthly!$D:$D,MATCH($B18,Monthly!$A:$A,0)) -> standalone | F18: =INDEX(Monthly!$E:$E,MATCH($B18,Monthly!$A:$A,0)) -> 366.89773 | G18: =INDEX(Monthly!$F:$F,MATCH($B18,Monthly!$A:$A,0)) -> 442.15042 | H18: =INDEX(Monthly!$G:$G,MATCH($B18,Monthly!$A:$A,0)) -> 32.860197 | I18: =$C$22/C18 -> 1.5678997 | J18: =$G$22/G18 -> 2.6750516 | K18: =$H$22/H18 -> 0.58611943
A19: Mar 2021 (first consolidated reading) | B19: =INDEX(Monthly!$A:$A,MATCH(DATE(2021,3,31),Monthly!$A:$A,1)) -> 44286 | C19: =INDEX(Monthly!$B:$B,MATCH($B19,Monthly!$A:$A,0)) -> 14690.7 | D19: =INDEX(Monthly!$C:$C,MATCH($B19,Monthly!$A:$A,0)) -> 33.2 | E19: =INDEX(Monthly!$D:$D,MATCH($B19,Monthly!$A:$A,0)) -> consolidated | F19: =INDEX(Monthly!$E:$E,MATCH($B19,Monthly!$A:$A,0)) -> 442.49096 | G19: =INDEX(Monthly!$F:$F,MATCH($B19,Monthly!$A:$A,0)) -> 442.49096 | H19: =INDEX(Monthly!$G:$G,MATCH($B19,Monthly!$A:$A,0)) -> 33.2 | I19: =$C$22/C19 -> 1.5506579 | J19: =$G$22/G19 -> 2.6729928 | K19: =$H$22/H19 -> 0.58012048
A20: Sep 2024 (record Nifty high month) | B20: =INDEX(Monthly!$A:$A,MATCH(DATE(2024,9,30),Monthly!$A:$A,1)) -> 45565 | C20: =INDEX(Monthly!$B:$B,MATCH($B20,Monthly!$A:$A,0)) -> 25810.85 | D20: =INDEX(Monthly!$C:$C,MATCH($B20,Monthly!$A:$A,0)) -> 24.3 | E20: =INDEX(Monthly!$D:$D,MATCH($B20,Monthly!$A:$A,0)) -> consolidated | F20: =INDEX(Monthly!$E:$E,MATCH($B20,Monthly!$A:$A,0)) -> 1062.1749 | G20: =INDEX(Monthly!$F:$F,MATCH($B20,Monthly!$A:$A,0)) -> 1062.1749 | H20: =INDEX(Monthly!$G:$G,MATCH($B20,Monthly!$A:$A,0)) -> 24.3 | I20: =$C$22/C20 -> 0.88258426 | J20: =$G$22/G20 -> 1.1135409 | K20: =$H$22/H20 -> 0.79259259
A21: End of 2025 | B21: =INDEX(Monthly!$A:$A,MATCH(DATE(2025,12,31),Monthly!$A:$A,1)) -> 46022 | C21: =INDEX(Monthly!$B:$B,MATCH($B21,Monthly!$A:$A,0)) -> 26129.6 | D21: =INDEX(Monthly!$C:$C,MATCH($B21,Monthly!$A:$A,0)) -> 22.75 | E21: =INDEX(Monthly!$D:$D,MATCH($B21,Monthly!$A:$A,0)) -> consolidated | F21: =INDEX(Monthly!$E:$E,MATCH($B21,Monthly!$A:$A,0)) -> 1148.5538 | G21: =INDEX(Monthly!$F:$F,MATCH($B21,Monthly!$A:$A,0)) -> 1148.5538 | H21: =INDEX(Monthly!$G:$G,MATCH($B21,Monthly!$A:$A,0)) -> 22.75 | I21: =$C$22/C21 -> 0.87181779 | J21: =$G$22/G21 -> 1.0297952 | K21: =$H$22/H21 -> 0.84659341
A22: Latest (28 Sep 2026) | B22: =INDEX(Monthly!$A:$A,122) -> 46293 | C22: =INDEX(Monthly!$B:$B,MATCH($B22,Monthly!$A:$A,0)) -> 22780.25 | D22: =INDEX(Monthly!$C:$C,MATCH($B22,Monthly!$A:$A,0)) -> 19.26 | E22: =INDEX(Monthly!$D:$D,MATCH($B22,Monthly!$A:$A,0)) -> consolidated | F22: =INDEX(Monthly!$E:$E,MATCH($B22,Monthly!$A:$A,0)) -> 1182.7752 | G22: =INDEX(Monthly!$F:$F,MATCH($B22,Monthly!$A:$A,0)) -> 1182.7752 | H22: =INDEX(Monthly!$G:$G,MATCH($B22,Monthly!$A:$A,0)) -> 19.26 | I22: =$C$22/C22 -> 1 | J22: =$G$22/G22 -> 1 | K22: =$H$22/H22 -> 1
A24: Two halves of the decade (as published; the second half crosses the 2021 switch, see the like-for-like range below)
A25: Period | B25: From | C25: To | D25: Price change | E25: EPS change as published | F25: P/E change as published | G25: Price CAGR
A26: Sep 2016 to Dec 2019 (both standalone: like-for-like) | B26: =B15 -> 42643 | C26: =B16 -> 43830 | D26: =C16/C15-1 -> 0.41310394 | E26: =F16/F15-1 -> 0.16843223 | F26: =D16/D15-1 -> 0.20940171 | G26: =(C16/C15)^(365.25/(B16-B15))-1 -> 0.11226904
A27: Dec 2019 to latest | B27: =B16 -> 43830 | C27: =B22 -> 46293 | D27: =C22/C16-1 -> 0.87207492 | E27: =F22/F16-1 -> 1.7507643 | F27: =D22/D16-1 -> -0.31943463 | G27: =(C22/C16)^(365.25/(B22-B16))-1 -> 0.097448395
A28: Whole decade | B28: =B15 -> 42643 | C28: =B22 -> 46293 | D28: =C22/C15-1 -> 1.6454364 | E28: =F22/F15-1 -> 2.2140817 | F28: =D22/D15-1 -> -0.17692308 | G28: =(C22/C15)^(365.25/(B22-B15))-1 -> 0.10224635
A31: Like-for-like range: pre-2021 earnings restated to a consolidated basis
A32: Measure | B32: Ratio 1.05 (PrimeInvestor, low) | C32: Ratio 1.14 (Bloomberg 10-yr average) | D32: Switch-day ratio
A33: Ratio | B33: =$B$12 -> 1.05 | C33: =$B$10 -> 1.14 | D33: =$B$9 -> 1.2051054
A34: Earnings multiple over the decade | B34: =$F$22/($F$15*$B$33) -> 3.0610301 | C34: =$F$22/($F$15*$C$33) -> 2.8193699 | D34: =$F$22/($F$15*$D$33) -> 2.6670545
A35: P/E ten years ago, restated | B35: =$D$15/$B$33 -> 22.285714 | C35: =$D$15/$C$33 -> 20.526316 | D35: =$D$15/$D$33 -> 19.417389
A36: Change in P/E over the decade | B36: =$D$22/($D$15/$B$33)-1 -> -0.13576923 | C36: =$D$22/($D$15/$C$33)-1 -> -0.061692308 | D36: =$D$22/($D$15/$D$33)-1 -> -0.0081055834
A37: Earnings multiple, Dec 2019 to latest | B37: =$F$22/($F$16*$B$33) -> 2.6197755 | C37: =$F$22/($F$16*$C$33) -> 2.4129511 | D37: =$F$22/($F$16*$D$33) -> 2.2825923
A38: P/E at end-2019, restated | B38: =$D$16/$B$33 -> 26.952381 | C38: =$D$16/$C$33 -> 24.824561 | D38: =$D$16/$D$33 -> 23.483424
A39: Change in P/E, Dec 2019 to latest | B39: =$D$22/($D$16/$B$33)-1 -> -0.28540636 | C39: =$D$22/($D$16/$C$33)-1 -> -0.22415548 | D39: =$D$22/($D$16/$D$33)-1 -> -0.17984702
A40: P/E in March 2020, restated | B40: =$D$17/$B$33 -> 18.47619 | C40: =$D$17/$C$33 -> 17.017544 | D40: =$D$17/$D$33 -> 16.098177
A42: Where today's P/E sits
A43: Lowest month-end NSE P/E since the switch (Mar 2021 onward) | B43: =MIN(Monthly!$C$56:$C$122) -> 19.26 | C43: =INDEX(Monthly!$A$56:$A$122,MATCH(B43,Monthly!$C$56:$C$122,0)) -> 46293
A44: Median month-end NSE P/E since the switch | B44: =MEDIAN(Monthly!$C$56:$C$122) -> 22
A45: Second-lowest month-end reading since the switch | B45: =SMALL(Monthly!$C$56:$C$122,2) -> 19.5 | C45: =INDEX(Monthly!$A$56:$A$122,MATCH(B45,Monthly!$C$56:$C$122,0)) -> 44742
A46: Median month-end NSE P/E, Sep 2016 to Feb 2021 (standalone, as published) | B46: =MEDIAN(Monthly!$C$2:$C$55) -> 26.35
...

Sheet Validation
A1: A. NSE P/E: Downstox values checked against NSE's own Index Dashboards and Nippon India notes
A2: Date | B2: Downstox (used) | C2: Second source | D2: Difference | E2: Second source | F2: Type | G2: URL
A3: 42734 | B3: 21.93 | C3: 21.93 | D3: =ROUND(C3-B3,2) -> 0 | E3: NSE Indices, Index Dashboard Dec 2016 | F3: primary, month-end | G3: https://mondovisione.com/_assets/files/IISL_Index_Dashboard_DEC2016.pdf
A4: 42825 | B4: 23.3 | C4: 23.26 | D4: =ROUND(C4-B4,2) -> -0.04 | E4: Nippon India MF, Markets for You (NSE data) | F4: month-end | G4: https://mf.nipponindiaim.com/LearnAndInvest/MarketsForYouDocuments/Markets-for-You-April-03-2017.pdf
A5: 43098 | B5: 26.92 | C5: 26.92 | D5: =ROUND(C5-B5,2) -> 0 | E5: Nippon India MF, Markets for You (NSE data) | F5: month-end | G5: https://mf.nipponindiaim.com/LearnAndInvest/MarketsForYouDocuments/Markets-for-You-January-01-2018.pdf
A6: 43131 | B6: 27.5 | C6: 27.5 | D6: =ROUND(C6-B6,2) -> 0 | E6: NSE Indices, Index Dashboard Jan 2018 | F6: primary, month-end | G6: https://mondovisione.com/_assets/files/IISL_Index_Dashboard_JAN2018.pdf
A7: 43343 | B7: 28.4 | C7: 28.4 | D7: =ROUND(C7-B7,2) -> 0 | E7: Nippon India MF, Markets for You (NSE data) | F7: month-end | G7: https://mf.nipponindiaim.com/LearnAndInvest/MarketsForYouDocuments/Markets-for-You-September-03-2018.pdf
A8: 43465 | B8: 26.17 | C8: 26.17 | D8: =ROUND(C8-B8,2) -> 0 | E8: Nippon India MF, Markets for You (NSE data) | F8: month-end | G8: https://mf.nipponindiaim.com/LearnAndInvest/MarketsForYouDocuments/Markets-for-You-January-01-2019.pdf
A9: 43553 | B9: 29 | C9: 29.01 | D9: =ROUND(C9-B9,2) -> 0.01 | E9: NSE Indices, Index Dashboard Mar 2019 | F9: primary, month-end | G9: https://mondovisione.com/_assets/files/Index_Dashboard_MAR2019.pdf
A10: 43644 | B10: 29 | C10: 28.98 | D10: =ROUND(C10-B10,2) -> -0.02 | E10: Nippon India MF, Markets for You (NSE data) | F10: month-end | G10: https://mf.nipponindiaim.com/LearnAndInvest/MarketsForYouDocuments/Markets-for-You-July-01-2019.pdf
A11: 43830 | B11: 28.3 | C11: 28.3 | D11: =ROUND(C11-B11,2) -> 0 | E11: NSE Indices, Index Dashboard Dec 2019 | F11: primary, month-end | G11: https://mondovisione.com/_assets/files/NSE_Index_Dashboard_DEC2019.pdf
A12: 43921 | B12: 19.4 | C12: 19.38 | D12: =ROUND(C12-B12,2) -> -0.02 | E12: NSE Indices, Index Dashboard Mar 2020 | F12: primary, month-end | G12: https://mondovisione.com/_assets/files/Index_Dashboard_MAR2020.pdf
A13: 44012 | B13: 26.3 | C13: 26.32 | D13: =ROUND(C13-B13,2) -> 0.02 | E13: NSE Indices, Index Dashboard Jun 2020 | F13: primary, month-end | G13: https://mondovisione.com/_assets/files/NSE_Index_Dashboard_JUN2020.pdf
A14: 44196 | B14: 38.45 | C14: 38.45 | D14: =ROUND(C14-B14,2) -> 0 | E14: NSE Indices, Index Dashboard Dec 2020 | F14: primary, month-end | G14: https://mondovisione.com/_assets/files/NSE_Index_Dashboard_DEC2020.pdf
... A28: 46265 | B28: 20.4 | C28: 20.36 | D28: =ROUND(C28-B28,2) -> -0.04 | E28: NSE Indices factsheet and Index Dashboard Aug 2026 | F28: primary, month-end | G28: https://www.niftyindices.com/Factsheet/ind_nifty50.pdf
A29: Largest absolute difference | D29: =SUMPRODUCT(MAX(ABS(D3:D28))) -> 0.08
A30: Downstox shows one decimal except at year-ends, so differences up to 0.05 are rounding.
A32: B. How much bigger were consolidated earnings than standalone? (the ratio used to restate pre-2021 numbers)
A33: When | B33: Ratio | E33: Source | G33: URL
A34: 31 Mar 2021, NSE switch day (this workbook, Summary!B9) | B34: =Summary!B9 -> 1.2051054 | E34: NSE P/E 40.43 on 30 Mar (standalone) and 33.20 on 31 Mar (consolidated) | G34: https://downstox.com/nifty-pe/nifty-50
A35: Early 2021, earnings to Dec 2020 (Bloomberg data) | B35: 1.16 | E35: The Hindu BusinessLine (Mar 2021): "about 16 per cent higher"; the article's own figures (Rs 420 vs Rs 371) imply about 13% | G35: https://www.thehindubusinessline.com/todays-paper/tp-investmentworld/article34010344.ece
A36: Average of the 10 years to 2020 (Bloomberg data) | B36: 1.14 | E36: The Hindu BusinessLine (Mar 2021): "on the average ... 14 per cent higher" | G36: https://www.thehindubusinessline.com/todays-paper/tp-investmentworld/article34010344.ece
A37: Jan 2008 peak (P/E 26.5 standalone vs 23.3 consolidated) | B37: 1.137 | E37: The Hindu BusinessLine (Bloomberg data) | G37: https://www.thehindubusinessline.com/todays-paper/tp-investmentworld/article34010344.ece
A38: Dec 2019 (low estimate) | B38: 1.05 | E38: PrimeInvestor (Dec 2019): "consolidated earnings of the Nifty firms are about 5 per cent higher than the standalone earnings" | G38: https://primeinvestor.in/reports/what-they-dont-tell-you-about-the-nifty-pe/
A40: C. Actual Nifty EPS tallied by Motilal Oswal (fiscal years ending March) vs NSE-implied trailing EPS two months after year-end
A41: Fiscal year | B41: MOFSL EPS (₹) | C41: NSE-implied EPS end-May, as published (₹) | D41: NSE / MOFSL | E41: Note / source
A42: FY16 | B42: 393 | E42: MOFSL India Strategy (Mar 2017): "the eventual FY16 EPS (~INR393)"; before this workbook's window
A43: FY19 | B43: 481 | C43: =INDEX(Monthly!$E:$E,MATCH(DATE(2019,5,31),Monthly!$A:$A,1)) -> 404.16271 | D43: =C43/B43 -> 0.84025512 | E43: MOFSL (Jun 2019), +6.7% YoY
A44: FY21 | B44: 539 | C44: =INDEX(Monthly!$E:$E,MATCH(DATE(2021,5,31),Monthly!$A:$A,1)) -> 533.65753 | D44: =C44/B44 -> 0.99008819 | E44: MOFSL via Mint (Jun 2021); first year where NSE is also on consolidated earnings
A45: FY22 | B45: 737 | C45: =INDEX(Monthly!$E:$E,MATCH(DATE(2022,5,31),Monthly!$A:$A,1)) -> 812.96814 | D45: =C45/B45 -> 1.1030775 | E45: MOFSL interim 4QFY22 review via Zee Business/PTI (May 2022)
A46: FY23 | B46: 806 | C46: =INDEX(Monthly!$E:$E,MATCH(DATE(2023,5,31),Monthly!$A:$A,1)) -> 858.07407 | D46: =C46/B46 -> 1.064608 | E46: MOFSL via BQ Prime (Jul 2023)
A47: FY24 | B47: 1005 | C47: =INDEX(Monthly!$E:$E,MATCH(DATE(2024,5,31),Monthly!$A:$A,1)) -> 1052.8364 | D47: =C47/B47 -> 1.0475985 | E47: MOFSL (31 May 2024), +24% YoY
A48: FY25 | B48: 1013 | C48: =INDEX(Monthly!$E:$E,MATCH(DATE(2025,5,31),Monthly!$A:$A,1)) -> 1109.8969 | D48: =C48/B48 -> 1.0956534 | E48: MOFSL (Jun 2025), +1% YoY
A49: FY26 | B49: 1065 | C49: =INDEX(Monthly!$E:$E,MATCH(DATE(2026,5,31),Monthly!$A:$A,1)) -> 1159.9877 | D49: =C49/B49 -> 1.0891903 | E49: MOFSL via ET Now / The Adviser Times (Jun 2026), +5% YoY
A50: MOFSL FY16 to FY26 EPS multiple | B50: =B49/B42 -> 2.7099237
A51: When both are on consolidated earnings (FY21) the two agree within 1%. In FY19, NSE's standalone figure sat well below MOFSL's, which is consistent with a large consolidated premium before 2021. The two methods drift apart by 5-9% in later years, so treat this as a rough cross-check.

Sheet Method & Sources
A1: How this workbook was built
A2: 1. Nifty 50 daily closes, 1 Sep 2016 to 28 Sep 2026, come from Yahoo Finance (^NSEI, NSE data). Every year was transcribed twice by independent agents and the two copies were diffed: all 2,483 days in Yahoo's daily table matched, and every month-end close matches Yahoo's monthly table. The one missing day (29 Mar 2019) was filled from Yahoo's monthly table, making 2,484 days.
A3: 2. NSE's Nifty 50 P/E (index market cap divided by trailing four-quarter earnings, as NSE Indices publishes it daily) is taken at each month-end from Downstox, which republishes NSE's series. 25 month-end values plus the 30 Mar 2021 daily reading were checked against NSE's own monthly Index Dashboards and Nippon India MF's notes; all but one agree within 0.05 (Downstox's one-decimal rounding) and the largest gap is 0.08 (Jul 2026, against a Nippon India product note). September 2026 uses the 28 Sep 2026 daily reading (19.26), not a month-end.
A4: 3. Earnings per unit = Nifty close / NSE P/E. This is NSE's trailing earnings for the index, as NSE counts them.
A5: 4. On 31 Mar 2021 NSE switched from standalone to consolidated earnings. The P/E fell from 40.43 to 33.20 overnight while the index moved about 1%, so consolidated earnings were about 20.5% higher than standalone that day (Summary!B9).
A6: 5. Like-for-like columns multiply pre-2021 earnings by a ratio (Summary!B11) to put them on a consolidated basis. The ratio changed over time: Bloomberg data put the 10-year average at 1.14 and early 2021 at about 1.13 to 1.16, NSE's switch day gave 1.205, and PrimeInvestor estimated only 1.05 in Dec 2019. The Summary shows results at 1.05, 1.14 and 1.205; the chart uses 1.14 to 1.205, the range best supported by NSE's own data and Bloomberg.
A7: 6. Motilal Oswal's bottom-up tally of actual Nifty EPS (FY16 ₹393 to FY26 ₹1,065, 2.7x) is shown on the Validation sheet as an independent check.
A9: What the numbers are, and what they are not
A10: NSE's P/E is a trailing measure: it divides today's price by the last four quarters of reported profit. It is not the forward (expected-earnings) P/E that Bloomberg charts use, so its levels are higher; on 28 Sep 2026 NSE showed 19.3x while Bloomberg's forward P/E was about 17x.
A11: Some long-run "average Nifty P/E" figures (Business Standard 26.7x, Craytheon 23.28x over 10 years) include the higher standalone readings from before 2021, which makes today's P/E look further below normal than it is like-for-like. The consolidated-era median here is 22.0x.
A12: The Nifty figures are the price index, without dividends. The total-return index grew about 1.35 percentage points a year faster over the ten years to 17 Jul 2026 (12.39% against 11.04% a year; NSE return profile via Bajaj Finserv AMC).
A14: Sources
... A24: PrimeInvestor (Dec 2019): consolidated Nifty earnings "about 5 per cent higher than the standalone earnings".
